2024-12-02 19:33:50,499 - app - ERROR - Exception on /dataset/unsynchronized/19/ [GET]
Traceback (most recent call last):
  File "/home/paula-luna-navarro/uvlhub/venv/lib/python3.12/site-packages/flask/app.py", line 1473, in wsgi_app
    response = self.full_dispatch_request()
               ^^^^^^^^^^^^^^^^^^^^^^^^^^^^
  File "/home/paula-luna-navarro/uvlhub/venv/lib/python3.12/site-packages/flask/app.py", line 882, in full_dispatch_request
    rv = self.handle_user_exception(e)
         ^^^^^^^^^^^^^^^^^^^^^^^^^^^^^
  File "/home/paula-luna-navarro/uvlhub/venv/lib/python3.12/site-packages/flask_restful/__init__.py", line 298, in error_router
    return original_handler(e)
           ^^^^^^^^^^^^^^^^^^^
  File "/home/paula-luna-navarro/uvlhub/venv/lib/python3.12/site-packages/flask/app.py", line 880, in full_dispatch_request
    rv = self.dispatch_request()
         ^^^^^^^^^^^^^^^^^^^^^^^
  File "/home/paula-luna-navarro/uvlhub/venv/lib/python3.12/site-packages/flask/app.py", line 865, in dispatch_request
    return self.ensure_sync(self.view_functions[rule.endpoint])(**view_args)  # type: ignore[no-any-return]
           ^^^^^^^^^^^^^^^^^^^^^^^^^^^^^^^^^^^^^^^^^^^^^^^^^^^^^^^^^^^^^^^^^
  File "/home/paula-luna-navarro/uvlhub/venv/lib/python3.12/site-packages/flask_login/utils.py", line 290, in decorated_view
    return current_app.ensure_sync(func)(*args, **kwargs)
           ^^^^^^^^^^^^^^^^^^^^^^^^^^^^^^^^^^^^^^^^^^^^^^
  File "/home/paula-luna-navarro/uvlhub/app/modules/dataset/routes.py", line 303, in get_unsynchronized_dataset
    return render_template("dataset/view_dataset.html", dataset=dataset)
           ^^^^^^^^^^^^^^^^^^^^^^^^^^^^^^^^^^^^^^^^^^^^^^^^^^^^^^^^^^^^^
  File "/home/paula-luna-navarro/uvlhub/venv/lib/python3.12/site-packages/flask/templating.py", line 150, in render_template
    return _render(app, template, context)
           ^^^^^^^^^^^^^^^^^^^^^^^^^^^^^^^
  File "/home/paula-luna-navarro/uvlhub/venv/lib/python3.12/site-packages/flask/templating.py", line 131, in _render
    rv = template.render(context)
         ^^^^^^^^^^^^^^^^^^^^^^^^
  File "/home/paula-luna-navarro/uvlhub/venv/lib/python3.12/site-packages/jinja2/environment.py", line 1304, in render
    self.environment.handle_exception()
  File "/home/paula-luna-navarro/uvlhub/venv/lib/python3.12/site-packages/jinja2/environment.py", line 939, in handle_exception
    raise rewrite_traceback_stack(source=source)
  File "/home/paula-luna-navarro/uvlhub/app/modules/dataset/templates/dataset/view_dataset.html", line 1, in top-level template code
    {% extends "base_template.html" %}
    ^^^^^^^^^^^^^^^^^^^^^^^^^
  File "/home/paula-luna-navarro/uvlhub/app/templates/base_template.html", line 206, in top-level template code
    {% block content %}{% endblock %}
    ^^^^^^^^^^^^^^^^^^^^^^^^^
  File "/home/paula-luna-navarro/uvlhub/app/modules/dataset/templates/dataset/view_dataset.html", line 152, in block 'content'
    <a href="{{ url_for('zenodo.upload', dataset_id=dataset.id) }}" class="btn btn-success btn-sm" style="border-radius: 5px;">
    ^^^^^^^^^^^^^^^^^^^^^^^^^
  File "/home/paula-luna-navarro/uvlhub/venv/lib/python3.12/site-packages/flask/app.py", line 1084, in url_for
    return self.handle_url_build_error(error, endpoint, values)
           ^^^^^^^^^^^^^^^^^^^^^^^^^^^^^^^^^^^^^^^^^^^^^^^^^^^^
  File "/home/paula-luna-navarro/uvlhub/venv/lib/python3.12/site-packages/flask/app.py", line 1073, in url_for
    rv = url_adapter.build(  # type: ignore[union-attr]
         ^^^^^^^^^^^^^^^^^^^^^^^^^^^^^^^^^^^^^^^^^^^^^^
  File "/home/paula-luna-navarro/uvlhub/venv/lib/python3.12/site-packages/werkzeug/routing/map.py", line 924, in build
    raise BuildError(endpoint, values, method, self)
werkzeug.routing.exceptions.BuildError: Could not build url for endpoint 'zenodo.upload' with values ['dataset_id']. Did you mean 'fakenodo.upload_dataset' instead?
2024-12-02 19:33:50,505 - app - ERROR - Internal Server Error: 500 Internal Server Error: The server encountered an internal error and was unable to complete your request. Either the server is overloaded or there is an error in the application.
2024-12-02 19:33:51,388 - app - ERROR - Exception on /dataset/unsynchronized/19/ [GET]
Traceback (most recent call last):
  File "/home/paula-luna-navarro/uvlhub/venv/lib/python3.12/site-packages/flask/app.py", line 1473, in wsgi_app
    response = self.full_dispatch_request()
               ^^^^^^^^^^^^^^^^^^^^^^^^^^^^
  File "/home/paula-luna-navarro/uvlhub/venv/lib/python3.12/site-packages/flask/app.py", line 882, in full_dispatch_request
    rv = self.handle_user_exception(e)
         ^^^^^^^^^^^^^^^^^^^^^^^^^^^^^
  File "/home/paula-luna-navarro/uvlhub/venv/lib/python3.12/site-packages/flask_restful/__init__.py", line 298, in error_router
    return original_handler(e)
           ^^^^^^^^^^^^^^^^^^^
  File "/home/paula-luna-navarro/uvlhub/venv/lib/python3.12/site-packages/flask/app.py", line 880, in full_dispatch_request
    rv = self.dispatch_request()
         ^^^^^^^^^^^^^^^^^^^^^^^
  File "/home/paula-luna-navarro/uvlhub/venv/lib/python3.12/site-packages/flask/app.py", line 865, in dispatch_request
    return self.ensure_sync(self.view_functions[rule.endpoint])(**view_args)  # type: ignore[no-any-return]
           ^^^^^^^^^^^^^^^^^^^^^^^^^^^^^^^^^^^^^^^^^^^^^^^^^^^^^^^^^^^^^^^^^
  File "/home/paula-luna-navarro/uvlhub/venv/lib/python3.12/site-packages/flask_login/utils.py", line 290, in decorated_view
    return current_app.ensure_sync(func)(*args, **kwargs)
           ^^^^^^^^^^^^^^^^^^^^^^^^^^^^^^^^^^^^^^^^^^^^^^
  File "/home/paula-luna-navarro/uvlhub/app/modules/dataset/routes.py", line 303, in get_unsynchronized_dataset
    return render_template("dataset/view_dataset.html", dataset=dataset)
           ^^^^^^^^^^^^^^^^^^^^^^^^^^^^^^^^^^^^^^^^^^^^^^^^^^^^^^^^^^^^^
  File "/home/paula-luna-navarro/uvlhub/venv/lib/python3.12/site-packages/flask/templating.py", line 150, in render_template
    return _render(app, template, context)
           ^^^^^^^^^^^^^^^^^^^^^^^^^^^^^^^
  File "/home/paula-luna-navarro/uvlhub/venv/lib/python3.12/site-packages/flask/templating.py", line 131, in _render
    rv = template.render(context)
         ^^^^^^^^^^^^^^^^^^^^^^^^
  File "/home/paula-luna-navarro/uvlhub/venv/lib/python3.12/site-packages/jinja2/environment.py", line 1304, in render
    self.environment.handle_exception()
  File "/home/paula-luna-navarro/uvlhub/venv/lib/python3.12/site-packages/jinja2/environment.py", line 939, in handle_exception
    raise rewrite_traceback_stack(source=source)
  File "/home/paula-luna-navarro/uvlhub/app/modules/dataset/templates/dataset/view_dataset.html", line 1, in top-level template code
    {% extends "base_template.html" %}
    ^^^^^^^^^^^^^^^^^^^^^^^^^
  File "/home/paula-luna-navarro/uvlhub/app/templates/base_template.html", line 206, in top-level template code
    {% block content %}{% endblock %}
    ^^^^^^^^^^^^^^^^^^^^^^^^^
  File "/home/paula-luna-navarro/uvlhub/app/modules/dataset/templates/dataset/view_dataset.html", line 152, in block 'content'
    <a href="{{ url_for('zenodo.upload', dataset_id=dataset.id) }}" class="btn btn-success btn-sm" style="border-radius: 5px;">
    ^^^^^^^^^^^^^^^^^^^^^^^^^
  File "/home/paula-luna-navarro/uvlhub/venv/lib/python3.12/site-packages/flask/app.py", line 1084, in url_for
    return self.handle_url_build_error(error, endpoint, values)
           ^^^^^^^^^^^^^^^^^^^^^^^^^^^^^^^^^^^^^^^^^^^^^^^^^^^^
  File "/home/paula-luna-navarro/uvlhub/venv/lib/python3.12/site-packages/flask/app.py", line 1073, in url_for
    rv = url_adapter.build(  # type: ignore[union-attr]
         ^^^^^^^^^^^^^^^^^^^^^^^^^^^^^^^^^^^^^^^^^^^^^^
  File "/home/paula-luna-navarro/uvlhub/venv/lib/python3.12/site-packages/werkzeug/routing/map.py", line 924, in build
    raise BuildError(endpoint, values, method, self)
werkzeug.routing.exceptions.BuildError: Could not build url for endpoint 'zenodo.upload' with values ['dataset_id']. Did you mean 'fakenodo.upload_dataset' instead?
2024-12-02 19:33:51,391 - app - ERROR - Internal Server Error: 500 Internal Server Error: The server encountered an internal error and was unable to complete your request. Either the server is overloaded or there is an error in the application.
