2024-11-24 21:08:33,633 - app.modules.dataset.routes - ERROR - Exception while create dataset data in Zenodo Failed to create deposition. Error details: {'status': 403, 'message': 'Permission denied.'}
Traceback (most recent call last):
  File "/home/alvaro-martin/egc/uvlhub/app/modules/dataset/routes.py", line 71, in create_dataset
    zenodo_response_json = zenodo_service.create_new_deposition(dataset)
                           ^^^^^^^^^^^^^^^^^^^^^^^^^^^^^^^^^^^^^^^^^^^^^
  File "/home/alvaro-martin/egc/uvlhub/app/modules/zenodo/services.py", line 180, in create_new_deposition
    raise Exception(error_message)
Exception: Failed to create deposition. Error details: {'status': 403, 'message': 'Permission denied.'}
2024-11-24 21:09:09,043 - app.modules.dataset.routes - ERROR - Exception while create dataset data in Zenodo Failed to create deposition. Error details: {'status': 403, 'message': 'Permission denied.'}
Traceback (most recent call last):
  File "/home/alvaro-martin/egc/uvlhub/app/modules/dataset/routes.py", line 71, in create_dataset
    zenodo_response_json = zenodo_service.create_new_deposition(dataset)
                           ^^^^^^^^^^^^^^^^^^^^^^^^^^^^^^^^^^^^^^^^^^^^^
  File "/home/alvaro-martin/egc/uvlhub/app/modules/zenodo/services.py", line 180, in create_new_deposition
    raise Exception(error_message)
Exception: Failed to create deposition. Error details: {'status': 403, 'message': 'Permission denied.'}
2024-11-24 21:09:49,256 - app.modules.dataset.routes - ERROR - Exception while create dataset data in Zenodo Failed to create deposition. Error details: {'status': 403, 'message': 'Permission denied.'}
Traceback (most recent call last):
  File "/home/alvaro-martin/egc/uvlhub/app/modules/dataset/routes.py", line 71, in create_dataset
    zenodo_response_json = zenodo_service.create_new_deposition(dataset)
                           ^^^^^^^^^^^^^^^^^^^^^^^^^^^^^^^^^^^^^^^^^^^^^
  File "/home/alvaro-martin/egc/uvlhub/app/modules/zenodo/services.py", line 180, in create_new_deposition
    raise Exception(error_message)
Exception: Failed to create deposition. Error details: {'status': 403, 'message': 'Permission denied.'}
2024-11-24 21:11:28,195 - app.modules.dataset.routes - ERROR - Exception while create dataset data in Zenodo Failed to create deposition. Error details: {'status': 403, 'message': 'Permission denied.'}
Traceback (most recent call last):
  File "/home/alvaro-martin/egc/uvlhub/app/modules/dataset/routes.py", line 71, in create_dataset
    zenodo_response_json = zenodo_service.create_new_deposition(dataset)
                           ^^^^^^^^^^^^^^^^^^^^^^^^^^^^^^^^^^^^^^^^^^^^^
  File "/home/alvaro-martin/egc/uvlhub/app/modules/zenodo/services.py", line 180, in create_new_deposition
    raise Exception(error_message)
Exception: Failed to create deposition. Error details: {'status': 403, 'message': 'Permission denied.'}
2024-11-24 21:14:16,588 - app.modules.dataset.routes - ERROR - Exception while create dataset data in Zenodo Failed to create deposition. Error details: {'status': 403, 'message': 'Permission denied.'}
Traceback (most recent call last):
  File "/home/alvaro-martin/egc/uvlhub/app/modules/dataset/routes.py", line 71, in create_dataset
    zenodo_response_json = zenodo_service.create_new_deposition(dataset)
                           ^^^^^^^^^^^^^^^^^^^^^^^^^^^^^^^^^^^^^^^^^^^^^
  File "/home/alvaro-martin/egc/uvlhub/app/modules/zenodo/services.py", line 180, in create_new_deposition
    raise Exception(error_message)
Exception: Failed to create deposition. Error details: {'status': 403, 'message': 'Permission denied.'}
2024-11-24 21:14:56,065 - app.modules.dataset.routes - ERROR - Exception while create dataset data in Zenodo Failed to create deposition. Error details: {'status': 403, 'message': 'Permission denied.'}
Traceback (most recent call last):
  File "/home/alvaro-martin/egc/uvlhub/app/modules/dataset/routes.py", line 71, in create_dataset
    zenodo_response_json = zenodo_service.create_new_deposition(dataset)
                           ^^^^^^^^^^^^^^^^^^^^^^^^^^^^^^^^^^^^^^^^^^^^^
  File "/home/alvaro-martin/egc/uvlhub/app/modules/zenodo/services.py", line 180, in create_new_deposition
    raise Exception(error_message)
Exception: Failed to create deposition. Error details: {'status': 403, 'message': 'Permission denied.'}
2024-11-25 11:36:53,242 - app.modules.dataset.routes - ERROR - Exception while create dataset data in Zenodo Failed to create deposition. Error details: {'status': 403, 'message': 'Permission denied.'}
Traceback (most recent call last):
  File "/home/alvaro-martin/egc/uvlhub/app/modules/dataset/routes.py", line 71, in create_dataset
    zenodo_response_json = zenodo_service.create_new_deposition(dataset)
                           ^^^^^^^^^^^^^^^^^^^^^^^^^^^^^^^^^^^^^^^^^^^^^
  File "/home/alvaro-martin/egc/uvlhub/app/modules/zenodo/services.py", line 180, in create_new_deposition
    raise Exception(error_message)
Exception: Failed to create deposition. Error details: {'status': 403, 'message': 'Permission denied.'}
2024-11-25 11:43:42,041 - app.modules.dataset.routes - ERROR - Exception while create dataset data in Zenodo Failed to create deposition. Error details: {'status': 403, 'message': 'Permission denied.'}
Traceback (most recent call last):
  File "/home/alvaro-martin/egc/uvlhub/app/modules/dataset/routes.py", line 71, in create_dataset
    zenodo_response_json = zenodo_service.create_new_deposition(dataset)
                           ^^^^^^^^^^^^^^^^^^^^^^^^^^^^^^^^^^^^^^^^^^^^^
  File "/home/alvaro-martin/egc/uvlhub/app/modules/zenodo/services.py", line 180, in create_new_deposition
    raise Exception(error_message)
Exception: Failed to create deposition. Error details: {'status': 403, 'message': 'Permission denied.'}
2024-11-30 13:31:21,020 - app - ERROR - Exception on /ia [GET]
Traceback (most recent call last):
  File "/home/alvaro-martin/egc/uvlhub/venv/lib/python3.12/site-packages/flask/app.py", line 1473, in wsgi_app
    response = self.full_dispatch_request()
               ^^^^^^^^^^^^^^^^^^^^^^^^^^^^
  File "/home/alvaro-martin/egc/uvlhub/venv/lib/python3.12/site-packages/flask/app.py", line 882, in full_dispatch_request
    rv = self.handle_user_exception(e)
         ^^^^^^^^^^^^^^^^^^^^^^^^^^^^^
  File "/home/alvaro-martin/egc/uvlhub/venv/lib/python3.12/site-packages/flask_restful/__init__.py", line 298, in error_router
    return original_handler(e)
           ^^^^^^^^^^^^^^^^^^^
  File "/home/alvaro-martin/egc/uvlhub/venv/lib/python3.12/site-packages/flask/app.py", line 880, in full_dispatch_request
    rv = self.dispatch_request()
         ^^^^^^^^^^^^^^^^^^^^^^^
  File "/home/alvaro-martin/egc/uvlhub/venv/lib/python3.12/site-packages/flask/app.py", line 865, in dispatch_request
    return self.ensure_sync(self.view_functions[rule.endpoint])(**view_args)  # type: ignore[no-any-return]
           ^^^^^^^^^^^^^^^^^^^^^^^^^^^^^^^^^^^^^^^^^^^^^^^^^^^^^^^^^^^^^^^^^
  File "/home/alvaro-martin/egc/uvlhub/app/modules/ia/routes.py", line 10, in ia_page
    return render_template('ia.html')
           ^^^^^^^^^^^^^^^^^^^^^^^^^^
  File "/home/alvaro-martin/egc/uvlhub/venv/lib/python3.12/site-packages/flask/templating.py", line 150, in render_template
    return _render(app, template, context)
           ^^^^^^^^^^^^^^^^^^^^^^^^^^^^^^^
  File "/home/alvaro-martin/egc/uvlhub/venv/lib/python3.12/site-packages/flask/templating.py", line 131, in _render
    rv = template.render(context)
         ^^^^^^^^^^^^^^^^^^^^^^^^
  File "/home/alvaro-martin/egc/uvlhub/venv/lib/python3.12/site-packages/jinja2/environment.py", line 1304, in render
    self.environment.handle_exception()
  File "/home/alvaro-martin/egc/uvlhub/venv/lib/python3.12/site-packages/jinja2/environment.py", line 939, in handle_exception
    raise rewrite_traceback_stack(source=source)
  File "/home/alvaro-martin/egc/uvlhub/app/modules/ia/templates/ia.html", line 1, in top-level template code
    {% extends "base_template.html" %}
    ^^^^^^^^^^^^^^^^^^^^^^^^^
  File "/home/alvaro-martin/egc/uvlhub/app/templates/base_template.html", line 200, in top-level template code
    {% block content %}{% endblock %}
    ^^^^^^^^^^^^^^^^^^^^^^^^^
  File "/home/alvaro-martin/egc/uvlhub/app/modules/ia/templates/ia.html", line 11, in block 'content'
    <form method="post" action="{{ url_for('ia.process_query') }}">
    ^^^^^^^^^^^^^^^^^^^^^^^^^
  File "/home/alvaro-martin/egc/uvlhub/venv/lib/python3.12/site-packages/flask/app.py", line 1084, in url_for
    return self.handle_url_build_error(error, endpoint, values)
           ^^^^^^^^^^^^^^^^^^^^^^^^^^^^^^^^^^^^^^^^^^^^^^^^^^^^
  File "/home/alvaro-martin/egc/uvlhub/venv/lib/python3.12/site-packages/flask/app.py", line 1073, in url_for
    rv = url_adapter.build(  # type: ignore[union-attr]
         ^^^^^^^^^^^^^^^^^^^^^^^^^^^^^^^^^^^^^^^^^^^^^^
  File "/home/alvaro-martin/egc/uvlhub/venv/lib/python3.12/site-packages/werkzeug/routing/map.py", line 924, in build
    raise BuildError(endpoint, values, method, self)
werkzeug.routing.exceptions.BuildError: Could not build url for endpoint 'ia.process_query'. Did you mean 'auth.protected_api' instead?
2024-11-30 13:31:21,028 - app - ERROR - Internal Server Error: 500 Internal Server Error: The server encountered an internal error and was unable to complete your request. Either the server is overloaded or there is an error in the application.
