2024-11-19 09:09:30,251 - app.modules.dataset.routes - ERROR - Exception while create dataset data in Zenodo Failed to create deposition. Error details: {'status': 403, 'message': 'Permission denied.'}
Traceback (most recent call last):
  File "/home/alex/Desktop/EGC/uvlhub/app/modules/dataset/routes.py", line 71, in create_dataset
    zenodo_response_json = zenodo_service.create_new_deposition(dataset)
                           ^^^^^^^^^^^^^^^^^^^^^^^^^^^^^^^^^^^^^^^^^^^^^
  File "/home/alex/Desktop/EGC/uvlhub/app/modules/zenodo/services.py", line 180, in create_new_deposition
    raise Exception(error_message)
Exception: Failed to create deposition. Error details: {'status': 403, 'message': 'Permission denied.'}
2024-11-19 09:09:46,595 - app.modules.dataset.routes - ERROR - Exception while create dataset data in Zenodo Failed to create deposition. Error details: {'status': 403, 'message': 'Permission denied.'}
Traceback (most recent call last):
  File "/home/alex/Desktop/EGC/uvlhub/app/modules/dataset/routes.py", line 71, in create_dataset
    zenodo_response_json = zenodo_service.create_new_deposition(dataset)
                           ^^^^^^^^^^^^^^^^^^^^^^^^^^^^^^^^^^^^^^^^^^^^^
  File "/home/alex/Desktop/EGC/uvlhub/app/modules/zenodo/services.py", line 180, in create_new_deposition
    raise Exception(error_message)
Exception: Failed to create deposition. Error details: {'status': 403, 'message': 'Permission denied.'}
2024-11-19 09:14:19,839 - app.modules.dataset.routes - ERROR - Exception while create dataset data in Zenodo Failed to create deposition. Error details: {'status': 403, 'message': 'Permission denied.'}
Traceback (most recent call last):
  File "/home/alex/Desktop/EGC/uvlhub/app/modules/dataset/routes.py", line 71, in create_dataset
    zenodo_response_json = zenodo_service.create_new_deposition(dataset)
                           ^^^^^^^^^^^^^^^^^^^^^^^^^^^^^^^^^^^^^^^^^^^^^
  File "/home/alex/Desktop/EGC/uvlhub/app/modules/zenodo/services.py", line 180, in create_new_deposition
    raise Exception(error_message)
Exception: Failed to create deposition. Error details: {'status': 403, 'message': 'Permission denied.'}
2024-11-19 09:14:36,041 - app.modules.dataset.routes - ERROR - Exception while create dataset data in Zenodo Failed to create deposition. Error details: {'status': 403, 'message': 'Permission denied.'}
Traceback (most recent call last):
  File "/home/alex/Desktop/EGC/uvlhub/app/modules/dataset/routes.py", line 71, in create_dataset
    zenodo_response_json = zenodo_service.create_new_deposition(dataset)
                           ^^^^^^^^^^^^^^^^^^^^^^^^^^^^^^^^^^^^^^^^^^^^^
  File "/home/alex/Desktop/EGC/uvlhub/app/modules/zenodo/services.py", line 180, in create_new_deposition
    raise Exception(error_message)
Exception: Failed to create deposition. Error details: {'status': 403, 'message': 'Permission denied.'}
2024-11-19 09:22:16,291 - app.modules.dataset.routes - ERROR - Exception while create dataset data in Zenodo Failed to create deposition. Error details: {'status': 403, 'message': 'Permission denied.'}
Traceback (most recent call last):
  File "/home/alex/Desktop/EGC/uvlhub/app/modules/dataset/routes.py", line 71, in create_dataset
    zenodo_response_json = zenodo_service.create_new_deposition(dataset)
                           ^^^^^^^^^^^^^^^^^^^^^^^^^^^^^^^^^^^^^^^^^^^^^
  File "/home/alex/Desktop/EGC/uvlhub/app/modules/zenodo/services.py", line 180, in create_new_deposition
    raise Exception(error_message)
Exception: Failed to create deposition. Error details: {'status': 403, 'message': 'Permission denied.'}
2024-11-19 09:22:32,017 - app.modules.dataset.routes - ERROR - Exception while create dataset data in Zenodo Failed to create deposition. Error details: {'status': 403, 'message': 'Permission denied.'}
Traceback (most recent call last):
  File "/home/alex/Desktop/EGC/uvlhub/app/modules/dataset/routes.py", line 71, in create_dataset
    zenodo_response_json = zenodo_service.create_new_deposition(dataset)
                           ^^^^^^^^^^^^^^^^^^^^^^^^^^^^^^^^^^^^^^^^^^^^^
  File "/home/alex/Desktop/EGC/uvlhub/app/modules/zenodo/services.py", line 180, in create_new_deposition
    raise Exception(error_message)
Exception: Failed to create deposition. Error details: {'status': 403, 'message': 'Permission denied.'}
2024-11-19 09:36:18,000 - app.modules.dataset.routes - ERROR - Exception while create dataset data in Zenodo Failed to create deposition. Error details: {'status': 403, 'message': 'Permission denied.'}
Traceback (most recent call last):
  File "/home/alex/Desktop/EGC/uvlhub/app/modules/dataset/routes.py", line 71, in create_dataset
    zenodo_response_json = zenodo_service.create_new_deposition(dataset)
                           ^^^^^^^^^^^^^^^^^^^^^^^^^^^^^^^^^^^^^^^^^^^^^
  File "/home/alex/Desktop/EGC/uvlhub/app/modules/zenodo/services.py", line 180, in create_new_deposition
    raise Exception(error_message)
Exception: Failed to create deposition. Error details: {'status': 403, 'message': 'Permission denied.'}
2024-11-19 09:36:34,099 - app.modules.dataset.routes - ERROR - Exception while create dataset data in Zenodo Failed to create deposition. Error details: {'status': 403, 'message': 'Permission denied.'}
Traceback (most recent call last):
  File "/home/alex/Desktop/EGC/uvlhub/app/modules/dataset/routes.py", line 71, in create_dataset
    zenodo_response_json = zenodo_service.create_new_deposition(dataset)
                           ^^^^^^^^^^^^^^^^^^^^^^^^^^^^^^^^^^^^^^^^^^^^^
  File "/home/alex/Desktop/EGC/uvlhub/app/modules/zenodo/services.py", line 180, in create_new_deposition
    raise Exception(error_message)
Exception: Failed to create deposition. Error details: {'status': 403, 'message': 'Permission denied.'}
2024-11-19 09:41:11,386 - app.modules.dataset.routes - ERROR - Exception while create dataset data in Zenodo Failed to create deposition. Error details: {'status': 403, 'message': 'Permission denied.'}
Traceback (most recent call last):
  File "/home/alex/Desktop/EGC/uvlhub/app/modules/dataset/routes.py", line 71, in create_dataset
    zenodo_response_json = zenodo_service.create_new_deposition(dataset)
                           ^^^^^^^^^^^^^^^^^^^^^^^^^^^^^^^^^^^^^^^^^^^^^
  File "/home/alex/Desktop/EGC/uvlhub/app/modules/zenodo/services.py", line 180, in create_new_deposition
    raise Exception(error_message)
Exception: Failed to create deposition. Error details: {'status': 403, 'message': 'Permission denied.'}
2024-11-19 09:41:27,461 - app.modules.dataset.routes - ERROR - Exception while create dataset data in Zenodo Failed to create deposition. Error details: {'status': 403, 'message': 'Permission denied.'}
Traceback (most recent call last):
  File "/home/alex/Desktop/EGC/uvlhub/app/modules/dataset/routes.py", line 71, in create_dataset
    zenodo_response_json = zenodo_service.create_new_deposition(dataset)
                           ^^^^^^^^^^^^^^^^^^^^^^^^^^^^^^^^^^^^^^^^^^^^^
  File "/home/alex/Desktop/EGC/uvlhub/app/modules/zenodo/services.py", line 180, in create_new_deposition
    raise Exception(error_message)
Exception: Failed to create deposition. Error details: {'status': 403, 'message': 'Permission denied.'}
2024-11-19 09:43:58,758 - app.modules.dataset.routes - ERROR - Exception while create dataset data in Zenodo Failed to create deposition. Error details: {'status': 403, 'message': 'Permission denied.'}
Traceback (most recent call last):
  File "/home/alex/Desktop/EGC/uvlhub/app/modules/dataset/routes.py", line 71, in create_dataset
    zenodo_response_json = zenodo_service.create_new_deposition(dataset)
                           ^^^^^^^^^^^^^^^^^^^^^^^^^^^^^^^^^^^^^^^^^^^^^
  File "/home/alex/Desktop/EGC/uvlhub/app/modules/zenodo/services.py", line 180, in create_new_deposition
    raise Exception(error_message)
Exception: Failed to create deposition. Error details: {'status': 403, 'message': 'Permission denied.'}
2024-11-19 09:44:15,442 - app.modules.dataset.routes - ERROR - Exception while create dataset data in Zenodo Failed to create deposition. Error details: {'status': 403, 'message': 'Permission denied.'}
Traceback (most recent call last):
  File "/home/alex/Desktop/EGC/uvlhub/app/modules/dataset/routes.py", line 71, in create_dataset
    zenodo_response_json = zenodo_service.create_new_deposition(dataset)
                           ^^^^^^^^^^^^^^^^^^^^^^^^^^^^^^^^^^^^^^^^^^^^^
  File "/home/alex/Desktop/EGC/uvlhub/app/modules/zenodo/services.py", line 180, in create_new_deposition
    raise Exception(error_message)
Exception: Failed to create deposition. Error details: {'status': 403, 'message': 'Permission denied.'}
2024-11-19 09:47:24,802 - app.modules.dataset.routes - ERROR - Exception while create dataset data in Zenodo Failed to create deposition. Error details: {'status': 403, 'message': 'Permission denied.'}
Traceback (most recent call last):
  File "/home/alex/Desktop/EGC/uvlhub/app/modules/dataset/routes.py", line 71, in create_dataset
    zenodo_response_json = zenodo_service.create_new_deposition(dataset)
                           ^^^^^^^^^^^^^^^^^^^^^^^^^^^^^^^^^^^^^^^^^^^^^
  File "/home/alex/Desktop/EGC/uvlhub/app/modules/zenodo/services.py", line 180, in create_new_deposition
    raise Exception(error_message)
Exception: Failed to create deposition. Error details: {'status': 403, 'message': 'Permission denied.'}
2024-11-19 09:47:41,239 - app.modules.dataset.routes - ERROR - Exception while create dataset data in Zenodo Failed to create deposition. Error details: {'status': 403, 'message': 'Permission denied.'}
Traceback (most recent call last):
  File "/home/alex/Desktop/EGC/uvlhub/app/modules/dataset/routes.py", line 71, in create_dataset
    zenodo_response_json = zenodo_service.create_new_deposition(dataset)
                           ^^^^^^^^^^^^^^^^^^^^^^^^^^^^^^^^^^^^^^^^^^^^^
  File "/home/alex/Desktop/EGC/uvlhub/app/modules/zenodo/services.py", line 180, in create_new_deposition
    raise Exception(error_message)
Exception: Failed to create deposition. Error details: {'status': 403, 'message': 'Permission denied.'}
