2024-11-19 09:49:08,125 - app.modules.dataset.routes - ERROR - Exception while create dataset data in Zenodo Failed to create deposition. Error details: {'status': 403, 'message': 'Permission denied.'}
Traceback (most recent call last):
  File "/home/alex/Desktop/EGC/uvlhub/app/modules/dataset/routes.py", line 71, in create_dataset
    zenodo_response_json = zenodo_service.create_new_deposition(dataset)
                           ^^^^^^^^^^^^^^^^^^^^^^^^^^^^^^^^^^^^^^^^^^^^^
  File "/home/alex/Desktop/EGC/uvlhub/app/modules/zenodo/services.py", line 180, in create_new_deposition
    raise Exception(error_message)
Exception: Failed to create deposition. Error details: {'status': 403, 'message': 'Permission denied.'}
2024-11-19 09:49:24,944 - app.modules.dataset.routes - ERROR - Exception while create dataset data in Zenodo Failed to create deposition. Error details: {'status': 403, 'message': 'Permission denied.'}
Traceback (most recent call last):
  File "/home/alex/Desktop/EGC/uvlhub/app/modules/dataset/routes.py", line 71, in create_dataset
    zenodo_response_json = zenodo_service.create_new_deposition(dataset)
                           ^^^^^^^^^^^^^^^^^^^^^^^^^^^^^^^^^^^^^^^^^^^^^
  File "/home/alex/Desktop/EGC/uvlhub/app/modules/zenodo/services.py", line 180, in create_new_deposition
    raise Exception(error_message)
Exception: Failed to create deposition. Error details: {'status': 403, 'message': 'Permission denied.'}
2024-11-19 09:50:21,228 - app.modules.dataset.routes - ERROR - Exception while create dataset data in Zenodo Failed to create deposition. Error details: {'status': 403, 'message': 'Permission denied.'}
Traceback (most recent call last):
  File "/home/alex/Desktop/EGC/uvlhub/app/modules/dataset/routes.py", line 71, in create_dataset
    zenodo_response_json = zenodo_service.create_new_deposition(dataset)
                           ^^^^^^^^^^^^^^^^^^^^^^^^^^^^^^^^^^^^^^^^^^^^^
  File "/home/alex/Desktop/EGC/uvlhub/app/modules/zenodo/services.py", line 180, in create_new_deposition
    raise Exception(error_message)
Exception: Failed to create deposition. Error details: {'status': 403, 'message': 'Permission denied.'}
2024-11-19 09:50:37,427 - app.modules.dataset.routes - ERROR - Exception while create dataset data in Zenodo Failed to create deposition. Error details: {'status': 403, 'message': 'Permission denied.'}
Traceback (most recent call last):
  File "/home/alex/Desktop/EGC/uvlhub/app/modules/dataset/routes.py", line 71, in create_dataset
    zenodo_response_json = zenodo_service.create_new_deposition(dataset)
                           ^^^^^^^^^^^^^^^^^^^^^^^^^^^^^^^^^^^^^^^^^^^^^
  File "/home/alex/Desktop/EGC/uvlhub/app/modules/zenodo/services.py", line 180, in create_new_deposition
    raise Exception(error_message)
Exception: Failed to create deposition. Error details: {'status': 403, 'message': 'Permission denied.'}
2024-11-19 09:52:27,135 - app.modules.dataset.routes - ERROR - Exception while create dataset data in Zenodo Failed to create deposition. Error details: {'status': 403, 'message': 'Permission denied.'}
Traceback (most recent call last):
  File "/home/alex/Desktop/EGC/uvlhub/app/modules/dataset/routes.py", line 71, in create_dataset
    zenodo_response_json = zenodo_service.create_new_deposition(dataset)
                           ^^^^^^^^^^^^^^^^^^^^^^^^^^^^^^^^^^^^^^^^^^^^^
  File "/home/alex/Desktop/EGC/uvlhub/app/modules/zenodo/services.py", line 180, in create_new_deposition
    raise Exception(error_message)
Exception: Failed to create deposition. Error details: {'status': 403, 'message': 'Permission denied.'}
2024-11-19 09:52:43,752 - app.modules.dataset.routes - ERROR - Exception while create dataset data in Zenodo Failed to create deposition. Error details: {'status': 403, 'message': 'Permission denied.'}
Traceback (most recent call last):
  File "/home/alex/Desktop/EGC/uvlhub/app/modules/dataset/routes.py", line 71, in create_dataset
    zenodo_response_json = zenodo_service.create_new_deposition(dataset)
                           ^^^^^^^^^^^^^^^^^^^^^^^^^^^^^^^^^^^^^^^^^^^^^
  File "/home/alex/Desktop/EGC/uvlhub/app/modules/zenodo/services.py", line 180, in create_new_deposition
    raise Exception(error_message)
Exception: Failed to create deposition. Error details: {'status': 403, 'message': 'Permission denied.'}
2024-11-19 09:59:31,318 - app.modules.dataset.routes - ERROR - Exception while create dataset data in Zenodo Failed to create deposition. Error details: {'status': 403, 'message': 'Permission denied.'}
Traceback (most recent call last):
  File "/home/alex/Desktop/EGC/uvlhub/app/modules/dataset/routes.py", line 71, in create_dataset
    zenodo_response_json = zenodo_service.create_new_deposition(dataset)
                           ^^^^^^^^^^^^^^^^^^^^^^^^^^^^^^^^^^^^^^^^^^^^^
  File "/home/alex/Desktop/EGC/uvlhub/app/modules/zenodo/services.py", line 180, in create_new_deposition
    raise Exception(error_message)
Exception: Failed to create deposition. Error details: {'status': 403, 'message': 'Permission denied.'}
2024-11-19 09:59:47,745 - app.modules.dataset.routes - ERROR - Exception while create dataset data in Zenodo Failed to create deposition. Error details: {'status': 403, 'message': 'Permission denied.'}
Traceback (most recent call last):
  File "/home/alex/Desktop/EGC/uvlhub/app/modules/dataset/routes.py", line 71, in create_dataset
    zenodo_response_json = zenodo_service.create_new_deposition(dataset)
                           ^^^^^^^^^^^^^^^^^^^^^^^^^^^^^^^^^^^^^^^^^^^^^
  File "/home/alex/Desktop/EGC/uvlhub/app/modules/zenodo/services.py", line 180, in create_new_deposition
    raise Exception(error_message)
Exception: Failed to create deposition. Error details: {'status': 403, 'message': 'Permission denied.'}
2024-11-19 11:49:13,845 - app.modules.dataset.routes - ERROR - Exception while create dataset data in Zenodo Failed to create deposition. Error details: {'status': 403, 'message': 'Permission denied.'}
Traceback (most recent call last):
  File "/home/alex/Desktop/EGC/uvlhub/app/modules/dataset/routes.py", line 71, in create_dataset
    zenodo_response_json = zenodo_service.create_new_deposition(dataset)
                           ^^^^^^^^^^^^^^^^^^^^^^^^^^^^^^^^^^^^^^^^^^^^^
  File "/home/alex/Desktop/EGC/uvlhub/app/modules/zenodo/services.py", line 180, in create_new_deposition
    raise Exception(error_message)
Exception: Failed to create deposition. Error details: {'status': 403, 'message': 'Permission denied.'}
2024-11-19 11:50:05,382 - app.modules.dataset.routes - ERROR - Exception while create dataset data in Zenodo Failed to create deposition. Error details: {'status': 403, 'message': 'Permission denied.'}
Traceback (most recent call last):
  File "/home/alex/Desktop/EGC/uvlhub/app/modules/dataset/routes.py", line 71, in create_dataset
    zenodo_response_json = zenodo_service.create_new_deposition(dataset)
                           ^^^^^^^^^^^^^^^^^^^^^^^^^^^^^^^^^^^^^^^^^^^^^
  File "/home/alex/Desktop/EGC/uvlhub/app/modules/zenodo/services.py", line 180, in create_new_deposition
    raise Exception(error_message)
Exception: Failed to create deposition. Error details: {'status': 403, 'message': 'Permission denied.'}
